2022-11-13 16:09:43,094 ERROR: Exception on /login [POST] [in /home/littl3.1/.local/lib/python3.10/site-packages/flask/app.py:1741]
Traceback (most recent call last):
  File "/home/littl3.1/.local/lib/python3.10/site-packages/flask/app.py", line 2525, in wsgi_app
    response = self.full_dispatch_request()
  File "/home/littl3.1/.local/lib/python3.10/site-packages/flask/app.py", line 1822, in full_dispatch_request
    rv = self.handle_user_exception(e)
  File "/home/littl3.1/.local/lib/python3.10/site-packages/flask/app.py", line 1820, in full_dispatch_request
    rv = self.dispatch_request()
  File "/home/littl3.1/.local/lib/python3.10/site-packages/flask/app.py", line 1796, in dispatch_request
    return self.ensure_sync(self.view_functions[rule.endpoint])(**view_args)
  File "/home/littl3.1/Alfr3d/cassiop3ia/www/app/routes.py", line 98, in login
    if user is None or not user.check_password(form.password.data):
  File "/home/littl3.1/Alfr3d/cassiop3ia/www/app/models.py", line 32, in check_password
    return check_password_hash(self.password_hash, password)
  File "/home/littl3.1/.local/lib/python3.10/site-packages/werkzeug/security.py", line 103, in check_password_hash
    if pwhash.count("$") < 2:
AttributeError: 'NoneType' object has no attribute 'count'
2022-11-13 16:10:00,773 ERROR: Exception on /reset_password_request [POST] [in /home/littl3.1/.local/lib/python3.10/site-packages/flask/app.py:1741]
Traceback (most recent call last):
  File "/home/littl3.1/.local/lib/python3.10/site-packages/flask/app.py", line 2525, in wsgi_app
    response = self.full_dispatch_request()
  File "/home/littl3.1/.local/lib/python3.10/site-packages/flask/app.py", line 1822, in full_dispatch_request
    rv = self.handle_user_exception(e)
  File "/home/littl3.1/.local/lib/python3.10/site-packages/flask/app.py", line 1820, in full_dispatch_request
    rv = self.dispatch_request()
  File "/home/littl3.1/.local/lib/python3.10/site-packages/flask/app.py", line 1796, in dispatch_request
    return self.ensure_sync(self.view_functions[rule.endpoint])(**view_args)
  File "/home/littl3.1/Alfr3d/cassiop3ia/www/app/routes.py", line 149, in reset_password_request
    send_password_reset_email(user)
NameError: name 'send_password_reset_email' is not defined
2022-11-13 16:12:15,006 INFO: Cassiop3ia web startup [in /home/littl3.1/Alfr3d/cassiop3ia/www/app/__init__.py:49]
2022-11-13 16:38:47,253 INFO: Cassiop3ia web startup [in /home/littl3.1/Alfr3d/cassiop3ia/www/app/__init__.py:49]
2022-11-13 16:46:59,099 ERROR: Exception on /user/athos [GET] [in /home/littl3.1/.local/lib/python3.10/site-packages/flask/app.py:1741]
Traceback (most recent call last):
  File "/home/littl3.1/.local/lib/python3.10/site-packages/flask/app.py", line 2525, in wsgi_app
    response = self.full_dispatch_request()
  File "/home/littl3.1/.local/lib/python3.10/site-packages/flask/app.py", line 1822, in full_dispatch_request
    rv = self.handle_user_exception(e)
  File "/home/littl3.1/.local/lib/python3.10/site-packages/flask/app.py", line 1820, in full_dispatch_request
    rv = self.dispatch_request()
  File "/home/littl3.1/.local/lib/python3.10/site-packages/flask/app.py", line 1796, in dispatch_request
    return self.ensure_sync(self.view_functions[rule.endpoint])(**view_args)
  File "/home/littl3.1/.local/lib/python3.10/site-packages/flask_login/utils.py", line 290, in decorated_view
    return current_app.ensure_sync(func)(*args, **kwargs)
  File "/home/littl3.1/Alfr3d/cassiop3ia/www/app/routes.py", line 139, in user
    return render_template('user.html', title=user.username, user=user, posts=posts, devices=devices)
  File "/home/littl3.1/.local/lib/python3.10/site-packages/flask/templating.py", line 147, in render_template
    return _render(app, template, context)
  File "/home/littl3.1/.local/lib/python3.10/site-packages/flask/templating.py", line 130, in _render
    rv = template.render(context)
  File "/home/littl3.1/.local/lib/python3.10/site-packages/jinja2/environment.py", line 1301, in render
    self.environment.handle_exception()
  File "/home/littl3.1/.local/lib/python3.10/site-packages/jinja2/environment.py", line 936, in handle_exception
    raise rewrite_traceback_stack(source=source)
  File "/home/littl3.1/Alfr3d/cassiop3ia/www/app/templates/user.html", line 1, in top-level template code
    {% extends "base.html" %}
  File "/home/littl3.1/Alfr3d/cassiop3ia/www/app/templates/base.html", line 1, in top-level template code
    {% extends 'bootstrap/base.html' %}
  File "/home/littl3.1/.local/lib/python3.10/site-packages/flask_bootstrap/templates/bootstrap/base.html", line 1, in top-level template code
    {% block doc -%}
  File "/home/littl3.1/.local/lib/python3.10/site-packages/flask_bootstrap/templates/bootstrap/base.html", line 4, in block 'doc'
    {%- block html %}
  File "/home/littl3.1/.local/lib/python3.10/site-packages/flask_bootstrap/templates/bootstrap/base.html", line 20, in block 'html'
    {% block body -%}
  File "/home/littl3.1/.local/lib/python3.10/site-packages/flask_bootstrap/templates/bootstrap/base.html", line 23, in block 'body'
    {% block content -%}
  File "/home/littl3.1/Alfr3d/cassiop3ia/www/app/templates/base.html", line 54, in block 'content'
    {% block app_content %}{% endblock %}
  File "/home/littl3.1/Alfr3d/cassiop3ia/www/app/templates/user.html", line 18, in block 'app_content'
    User Type: {{ user.user_type.type }} <br>
  File "/home/littl3.1/.local/lib/python3.10/site-packages/jinja2/environment.py", line 485, in getattr
    return getattr(obj, attribute)
jinja2.exceptions.UndefinedError: 'app.models.User object' has no attribute 'user_type'
2022-11-13 16:47:58,394 ERROR: Exception on /user/athos [GET] [in /home/littl3.1/.local/lib/python3.10/site-packages/flask/app.py:1741]
Traceback (most recent call last):
  File "/home/littl3.1/.local/lib/python3.10/site-packages/flask/app.py", line 2525, in wsgi_app
    response = self.full_dispatch_request()
  File "/home/littl3.1/.local/lib/python3.10/site-packages/flask/app.py", line 1822, in full_dispatch_request
    rv = self.handle_user_exception(e)
  File "/home/littl3.1/.local/lib/python3.10/site-packages/flask/app.py", line 1820, in full_dispatch_request
    rv = self.dispatch_request()
  File "/home/littl3.1/.local/lib/python3.10/site-packages/flask/app.py", line 1796, in dispatch_request
    return self.ensure_sync(self.view_functions[rule.endpoint])(**view_args)
  File "/home/littl3.1/.local/lib/python3.10/site-packages/flask_login/utils.py", line 290, in decorated_view
    return current_app.ensure_sync(func)(*args, **kwargs)
  File "/home/littl3.1/Alfr3d/cassiop3ia/www/app/routes.py", line 139, in user
    return render_template('user.html', title=user.username, user=user, posts=posts, devices=devices)
  File "/home/littl3.1/.local/lib/python3.10/site-packages/flask/templating.py", line 147, in render_template
    return _render(app, template, context)
  File "/home/littl3.1/.local/lib/python3.10/site-packages/flask/templating.py", line 130, in _render
    rv = template.render(context)
  File "/home/littl3.1/.local/lib/python3.10/site-packages/jinja2/environment.py", line 1301, in render
    self.environment.handle_exception()
  File "/home/littl3.1/.local/lib/python3.10/site-packages/jinja2/environment.py", line 936, in handle_exception
    raise rewrite_traceback_stack(source=source)
  File "/home/littl3.1/Alfr3d/cassiop3ia/www/app/templates/user.html", line 1, in top-level template code
    {% extends "base.html" %}
  File "/home/littl3.1/Alfr3d/cassiop3ia/www/app/templates/base.html", line 1, in top-level template code
    {% extends 'bootstrap/base.html' %}
  File "/home/littl3.1/.local/lib/python3.10/site-packages/flask_bootstrap/templates/bootstrap/base.html", line 1, in top-level template code
    {% block doc -%}
  File "/home/littl3.1/.local/lib/python3.10/site-packages/flask_bootstrap/templates/bootstrap/base.html", line 4, in block 'doc'
    {%- block html %}
  File "/home/littl3.1/.local/lib/python3.10/site-packages/flask_bootstrap/templates/bootstrap/base.html", line 20, in block 'html'
    {% block body -%}
  File "/home/littl3.1/.local/lib/python3.10/site-packages/flask_bootstrap/templates/bootstrap/base.html", line 23, in block 'body'
    {% block content -%}
  File "/home/littl3.1/Alfr3d/cassiop3ia/www/app/templates/base.html", line 54, in block 'content'
    {% block app_content %}{% endblock %}
  File "/home/littl3.1/Alfr3d/cassiop3ia/www/app/templates/user.html", line 18, in block 'app_content'
    User Type: {{ user.user_type.type }} <br>
  File "/home/littl3.1/.local/lib/python3.10/site-packages/jinja2/environment.py", line 485, in getattr
    return getattr(obj, attribute)
jinja2.exceptions.UndefinedError: 'app.models.User object' has no attribute 'user_type'
